Workbook

Sheet orders
A1: order_id | B1: order_month | C1: first_name | D1: last_name | E1: clean_first_name | F1: clean_last_name | G1: region | H1: rep_name | I1: item | J1: category | K1: unit price | L1: quantity | M1: revenue_calc | N1: amount | O1: status
A2: 1001 | B2: 2026-09 | C2: MEERA | D2: Patil | E2: =PROPER(TRIM(C2)) -> Meera | F2: =PROPER(TRIM(D2)) -> Patil | G2: South | H2: Kavya Nair | I2: Bluetooth Speaker | J2: =VLOOKUP(I2,products!$A$2:$C$10,2,FALSE) -> Electronics | K2: =_xlfn.XLOOKUP(I2,products!$A$2:$A$10,products!$C$2:$C$10,"UNKNOWN_ITEM") -> 2800 | L2: 2 | M2: =K2*L2 -> 5600 | N2: NULL | O2: pending
A3: 1002 | B3: 2026-09 | C3: Nisha | D3: Mishra | E3: =PROPER(TRIM(C3)) -> Nisha | F3: =PROPER(TRIM(D3)) -> Mishra | G3: West | H3: Neha Kulkarni | I3: Smart Watch | J3: =VLOOKUP(I3,products!$A$2:$C$10,2,FALSE) -> Electronics | K3: =_xlfn.XLOOKUP(I3,products!$A$2:$A$10,products!$C$2:$C$10,"UNKNOWN_ITEM") -> 4500 | L3: 1 | M3: =K3*L3 -> 4500 | N3: 4500 | O3: pending
A4: 1003 | B4: 2026-09 | C4: Lakshmi | D4: Kapoor | E4: =PROPER(TRIM(C4)) -> Lakshmi | F4: =PROPER(TRIM(D4)) -> Kapoor | G4: South | H4: Kavya Nair | I4: Air Fryer | J4: =VLOOKUP(I4,products!$A$2:$C$10,2,FALSE) -> Home | K4: =_xlfn.XLOOKUP(I4,products!$A$2:$A$10,products!$C$2:$C$10,"UNKNOWN_ITEM") -> 5200 | L4: 2 | M4: =K4*L4 -> 10400 | N4: 10400 | O4: disputed
A5: 1004 | B5: 2026-09 | C5: Gaurav | D5: Yadav | E5: =PROPER(TRIM(C5)) -> Gaurav | F5: =PROPER(TRIM(D5)) -> Yadav | G5: East | H5: Sanjay Roy | I5: Cotton Kurta | J5: =VLOOKUP(I5,products!$A$2:$C$10,2,FALSE) -> Apparel | K5: =_xlfn.XLOOKUP(I5,products!$A$2:$A$10,products!$C$2:$C$10,"UNKNOWN_ITEM") -> 1400 | L5: 2 | M5: =K5*L5 -> 2800 | N5: 2800 | O5: pending
A6: 1061 | B6: 2026-11 | C6: Nisha | D6: Mishra | E6: =PROPER(TRIM(C6)) -> Nisha | F6: =PROPER(TRIM(D6)) -> Mishra | G6: West | H6: Neha Kulkarni | I6: Air Fryer | J6: =VLOOKUP(I6,products!$A$2:$C$10,2,FALSE) -> Home | K6: =_xlfn.XLOOKUP(I6,products!$A$2:$A$10,products!$C$2:$C$10,"UNKNOWN_ITEM") -> 5200 | L6: 3 | M6: =K6*L6 -> 15600 | N6: 15600 | O6: completed
A7: 1065 | B7: 2026-11 | C7: Tanvi | D7: Thakur | E7: =PROPER(TRIM(C7)) -> Tanvi | F7: =PROPER(TRIM(D7)) -> Thakur | G7: South | H7: Kavya Nair | I7: Air Fryer | J7: =VLOOKUP(I7,products!$A$2:$C$10,2,FALSE) -> Home | K7: =_xlfn.XLOOKUP(I7,products!$A$2:$A$10,products!$C$2:$C$10,"UNKNOWN_ITEM") -> 5200 | L7: 3 | M7: =K7*L7 -> 15600 | N7: 15600 | O7: completed
A8: 1069 | B8: 2026-11 | C8: Aditya | D8: Rao | E8: =PROPER(TRIM(C8)) -> Aditya | F8: =PROPER(TRIM(D8)) -> Rao | G8: East | H8: Sanjay Roy | I8: Air Fryer | J8: =VLOOKUP(I8,products!$A$2:$C$10,2,FALSE) -> Home | K8: =_xlfn.XLOOKUP(I8,products!$A$2:$A$10,products!$C$2:$C$10,"UNKNOWN_ITEM") -> 5200 | L8: 3 | M8: =K8*L8 -> 15600 | N8: 15600 | O8: completed
A9: 1077 | B9: 2026-11 | C9: RAHUL | D9: VERMA | E9: =PROPER(TRIM(C9)) -> Rahul | F9: =PROPER(TRIM(D9)) -> Verma | G9: East | H9: Sanjay Roy | I9: Air Fryer | J9: =VLOOKUP(I9,products!$A$2:$C$10,2,FALSE) -> Home | K9: =_xlfn.XLOOKUP(I9,products!$A$2:$A$10,products!$C$2:$C$10,"UNKNOWN_ITEM") -> 5200 | L9: 3 | M9: =K9*L9 -> 15600 | N9: 15600 | O9: completed
A10: 1006 | B10: 2026-09 | C10: Vikram | D10: Singh | E10: =PROPER(TRIM(C10)) -> Vikram | F10: =PROPER(TRIM(D10)) -> Singh | G10: North | H10: Arjun Mehta | I10: Smart Watch | J10: =VLOOKUP(I10,products!$A$2:$C$10,2,FALSE) -> Electronics | K10: =_xlfn.XLOOKUP(I10,products!$A$2:$A$10,products!$C$2:$C$10,"UNKNOWN_ITEM") -> 4500 | L10: 3 | M10: =K10*L10 -> 13500 | N10: 13500 | O10: completed
A11: 1010 | B11: 2026-09 | C11: Gaurav | D11: Yadav | E11: =PROPER(TRIM(C11)) -> Gaurav | F11: =PROPER(TRIM(D11)) -> Yadav | G11: East | H11: Sanjay Roy | I11: Wireless Earbuds | J11: =VLOOKUP(I11,products!$A$2:$C$10,2,FALSE) -> Electronics | K11: =_xlfn.XLOOKUP(I11,products!$A$2:$A$10,products!$C$2:$C$10,"UNKNOWN_ITEM") -> 3200 | L11: 1 | M11: =K11*L11 -> 3200 | N11: NULL | O11: pending
A12: 1011 | B12: 2026-09 | C12: Isha | D12: Pillai | E12: =PROPER(TRIM(C12)) -> Isha | F12: =PROPER(TRIM(D12)) -> Pillai | G12: West | H12: Neha Kulkarni | I12: Air Fryer | J12: =VLOOKUP(I12,products!$A$2:$C$10,2,FALSE) -> Home | K12: =_xlfn.XLOOKUP(I12,products!$A$2:$A$10,products!$C$2:$C$10,"UNKNOWN_ITEM") -> 5200 | L12: 3 | M12: =K12*L12 -> 15600 | N12: 15600 | O12: disputed
A13: 1040 | B13: 2026-10 | C13: aarav | D13: Sharma | E13: =PROPER(TRIM(C13)) -> Aarav | F13: =PROPER(TRIM(D13)) -> Sharma | G13: North | H13: Arjun Mehta | I13: Smart Watch | J13: =VLOOKUP(I13,products!$A$2:$C$10,2,FALSE) -> Electronics | K13: =_xlfn.XLOOKUP(I13,products!$A$2:$A$10,products!$C$2:$C$10,"UNKNOWN_ITEM") -> 4500 | L13: 3 | M13: =K13*L13 -> 13500 | N13: 13500 | O13: completed
A14: 1013 | B14: 2026-09 | C14: Harsh | D14: Chopra | E14: =PROPER(TRIM(C14)) -> Harsh | F14: =PROPER(TRIM(D14)) -> Chopra | G14: East | H14: Sanjay Roy | I14: Smart Watch | J14: =VLOOKUP(I14,products!$A$2:$C$10,2,FALSE) -> Electronics | K14: =_xlfn.XLOOKUP(I14,products!$A$2:$A$10,products!$C$2:$C$10,"UNKNOWN_ITEM") -> 4500 | L14: 2 | M14: =K14*L14 -> 9000 | N14: 9000 | O14: disputed
A15: 1021 | B15: 2026-09 | C15: Manoj | D15: Desai | E15: =PROPER(TRIM(C15)) -> Manoj | F15: =PROPER(TRIM(D15)) -> Desai | G15: North | H15: Arjun Mehta | I15: Air Fryer | J15: =VLOOKUP(I15,products!$A$2:$C$10,2,FALSE) -> Home | K15: =_xlfn.XLOOKUP(I15,products!$A$2:$A$10,products!$C$2:$C$10,"UNKNOWN_ITEM") -> 5200 | L15: 2 | M15: =K15*L15 -> 10400 | N15: 10400 | O15: completed
A16: 1022 | B16: 2026-09 | C16: Vikram | D16: Singh | E16: =PROPER(TRIM(C16)) -> Vikram | F16: =PROPER(TRIM(D16)) -> Singh | G16: North | H16: Arjun Mehta | I16: Air Fryer | J16: =VLOOKUP(I16,products!$A$2:$C$10,2,FALSE) -> Home | K16: =_xlfn.XLOOKUP(I16,products!$A$2:$A$10,products!$C$2:$C$10,"UNKNOWN_ITEM") -> 5200 | L16: 2 | M16: =K16*L16 -> 10400 | N16: 10400 | O16: completed
A17: 1083 | B17: 2026-11 | C17: Lakshmi | D17: Kapoor | E17: =PROPER(TRIM(C17)) -> Lakshmi | F17: =PROPER(TRIM(D17)) -> Kapoor | G17: South | H17: Kavya Nair | I17: Air Fryer | J17: =VLOOKUP(I17,products!$A$2:$C$10,2,FALSE) -> Home | K17: =_xlfn.XLOOKUP(I17,products!$A$2:$A$10,products!$C$2:$C$10,"UNKNOWN_ITEM") -> 5200 | L17: 2 | M17: =K17*L17 -> 10400 | N17: 10400 | O17: completed
A18: 1054 | B18: 2026-10 | C18: Manoj | D18: Desai | E18: =PROPER(TRIM(C18)) -> Manoj | F18: =PROPER(TRIM(D18)) -> Desai | G18: North | H18: Arjun Mehta | I18: Wireless Earbuds | J18: =VLOOKUP(I18,products!$A$2:$C$10,2,FALSE) -> Electronics | K18: =_xlfn.XLOOKUP(I18,products!$A$2:$A$10,products!$C$2:$C$10,"UNKNOWN_ITEM") -> 3200 | L18: 3 | M18: =K18*L18 -> 9600 | N18: 9600 | O18: completed
A19: 1090 | B19: 2026-11 | C19: karthik | D19: nair | E19: =PROPER(TRIM(C19)) -> Karthik | F19: =PROPER(TRIM(D19)) -> Nair | G19: East | H19: Sanjay Roy | I19: Wireless Earbuds | J19: =VLOOKUP(I19,products!$A$2:$C$10,2,FALSE) -> Electronics | K19: =_xlfn.XLOOKUP(I19,products!$A$2:$A$10,products!$C$2:$C$10,"UNKNOWN_ITEM") -> 3200 | L19: 3 | M19: =K19*L19 -> 9600 | N19: 9600 | O19: completed
A20: 1015 | B20: 2026-09 | C20: Lakshmi | D20: Kapoor | E20: =PROPER(TRIM(C20)) -> Lakshmi | F20: =PROPER(TRIM(D20)) -> Kapoor | G20: South | H20: Kavya Nair | I20: Smart Watch | J20: =VLOOKUP(I20,products!$A$2:$C$10,2,FALSE) -> Electronics | K20: =_xlfn.XLOOKUP(I20,products!$A$2:$A$10,products!$C$2:$C$10,"UNKNOWN_ITEM") -> 4500 | L20: 2 | M20: =K20*L20 -> 9000 | N20: 9000 | O20: completed
A21: 1049 | B21: 2026-10 | C21: aarav | D21: Sharma | E21: =PROPER(TRIM(C21)) -> Aarav | F21: =PROPER(TRIM(D21)) -> Sharma | G21: North | H21: Arjun Mehta | I21: Smart Watch | J21: =VLOOKUP(I21,products!$A$2:$C$10,2,FALSE) -> Electronics | K21: =_xlfn.XLOOKUP(I21,products!$A$2:$A$10,products!$C$2:$C$10,"UNKNOWN_ITEM") -> 4500 | L21: 2 | M21: =K21*L21 -> 9000 | N21: 9000 | O21: completed
A22: 1016 | B22: 2026-09 | C22: Pooja | D22: Menon | E22: =PROPER(TRIM(C22)) -> Pooja | F22: =PROPER(TRIM(D22)) -> Menon | G22: West | H22: Neha Kulkarni | I22: Denim Jacket | J22: =VLOOKUP(I22,products!$A$2:$C$10,2,FALSE) -> Apparel | K22: =_xlfn.XLOOKUP(I22,products!$A$2:$A$10,products!$C$2:$C$10,"UNKNOWN_ITEM") -> 2500 | L22: 3 | M22: =K22*L22 -> 7500 | N22: 7500 | O22: completed
A23: 1019 | B23: 2026-09 | C23: Vikram | D23: Singh | E23: =PROPER(TRIM(C23)) -> Vikram | F23: =PROPER(TRIM(D23)) -> Singh | G23: North | H23: Arjun Mehta | I23: Running Shoes | J23: =VLOOKUP(I23,products!$A$2:$C$10,2,FALSE) -> Apparel | K23: =_xlfn.XLOOKUP(I23,products!$A$2:$A$10,products!$C$2:$C$10,"UNKNOWN_ITEM") -> 3600 | L23: 2 | M23: =K23*L23 -> 7200 | N23: 7200 | O23: completed
... A64: 1063 | B64: 2026-11 | C64: MEERA | D64: Patil | E64: =PROPER(TRIM(C64)) -> Meera | F64: =PROPER(TRIM(D64)) -> Patil | G64: South | H64: Kavya Nair | I64: Air Fryer | J64: =VLOOKUP(I64,products!$A$2:$C$10,2,FALSE) -> Home | K64: =_xlfn.XLOOKUP(I64,products!$A$2:$A$10,products!$C$2:$C$10,"UNKNOWN_ITEM") -> 5200 | L64: 1 | M64: =K64*L64 -> 5200 | N64: 5200 | O64: pending
A65: 1064 | B65: 2026-11 | C65: Isha | D65: Pillai | E65: =PROPER(TRIM(C65)) -> Isha | F65: =PROPER(TRIM(D65)) -> Pillai | G65: West | H65: Neha Kulkarni | I65: Bluetooth Speaker | J65: =VLOOKUP(I65,products!$A$2:$C$10,2,FALSE) -> Electronics | K65: =_xlfn.XLOOKUP(I65,products!$A$2:$A$10,products!$C$2:$C$10,"UNKNOWN_ITEM") -> 2800 | L65: 1 | M65: =K65*L65 -> 2800 | N65: NULL | O65: pending
A66: 1088 | B66: 2026-11 | C66: Sneha | D66: Das | E66: =PROPER(TRIM(C66)) -> Sneha | F66: =PROPER(TRIM(D66)) -> Das | G66: West | H66: Neha Kulkarni | I66: Wireless Earbuds | J66: =VLOOKUP(I66,products!$A$2:$C$10,2,FALSE) -> Electronics | K66: =_xlfn.XLOOKUP(I66,products!$A$2:$A$10,products!$C$2:$C$10,"UNKNOWN_ITEM") -> 3200 | L66: 1 | M66: =K66*L66 -> 3200 | N66: 3200 | O66: completed
A67: 1038 | B67: 2026-10 | C67: RAHUL | D67: VERMA | E67: =PROPER(TRIM(C67)) -> Rahul | F67: =PROPER(TRIM(D67)) -> Verma | G67: East | H67: Sanjay Roy | I67: Cotton Kurta | J67: =VLOOKUP(I67,products!$A$2:$C$10,2,FALSE) -> Apparel | K67: =_xlfn.XLOOKUP(I67,products!$A$2:$A$10,products!$C$2:$C$10,"UNKNOWN_ITEM") -> 1400 | L67: 2 | M67: =K67*L67 -> 2800 | N67: 2800 | O67: completed
A68: 1041 | B68: 2026-10 | C68: Divya | D68: Gupta | E68: =PROPER(TRIM(C68)) -> Divya | F68: =PROPER(TRIM(D68)) -> Gupta | G68: West | H68: Neha Kulkarni | I68: Bluetooth Speaker | J68: =VLOOKUP(I68,products!$A$2:$C$10,2,FALSE) -> Electronics | K68: =_xlfn.XLOOKUP(I68,products!$A$2:$A$10,products!$C$2:$C$10,"UNKNOWN_ITEM") -> 2800 | L68: 1 | M68: =K68*L68 -> 2800 | N68: 2800 | O68: completed
A69: 1068 | B69: 2026-11 | C69: Harsh | D69: Chopra | E69: =PROPER(TRIM(C69)) -> Harsh | F69: =PROPER(TRIM(D69)) -> Chopra | G69: East | H69: Sanjay Roy | I69: Air Fryer | J69: =VLOOKUP(I69,products!$A$2:$C$10,2,FALSE) -> Home | K69: =_xlfn.XLOOKUP(I69,products!$A$2:$A$10,products!$C$2:$C$10,"UNKNOWN_ITEM") -> 5200 | L69: 1 | M69: =K69*L69 -> 5200 | N69: 5200 | O69: pending
A70: 1043 | B70: 2026-10 | C70: Rohit | D70: Khan | E70: =PROPER(TRIM(C70)) -> Rohit | F70: =PROPER(TRIM(D70)) -> Khan | G70: North | H70: Arjun Mehta | I70: Bluetooth Speaker | J70: =VLOOKUP(I70,products!$A$2:$C$10,2,FALSE) -> Electronics | K70: =_xlfn.XLOOKUP(I70,products!$A$2:$A$10,products!$C$2:$C$10,"UNKNOWN_ITEM") -> 2800 | L70: 1 | M70: =K70*L70 -> 2800 | N70: 2800 | O70: completed
A71: 1051 | B71: 2026-10 | C71: Sneha | D71: Das | E71: =PROPER(TRIM(C71)) -> Sneha | F71: =PROPER(TRIM(D71)) -> Das | G71: West | H71: Neha Kulkarni | I71: Cotton Kurta | J71: =VLOOKUP(I71,products!$A$2:$C$10,2,FALSE) -> Apparel | K71: =_xlfn.XLOOKUP(I71,products!$A$2:$A$10,products!$C$2:$C$10,"UNKNOWN_ITEM") -> 1400 | L71: 2 | M71: =K71*L71 -> 2800 | N71: 2800 | O71: completed
A72: 1071 | B72: 2026-11 | C72: Tanvi | D72: Thakur | E72: =PROPER(TRIM(C72)) -> Tanvi | F72: =PROPER(TRIM(D72)) -> Thakur | G72: South | H72: Kavya Nair | I72: Air Fryer | J72: =VLOOKUP(I72,products!$A$2:$C$10,2,FALSE) -> Home | K72: =_xlfn.XLOOKUP(I72,products!$A$2:$A$10,products!$C$2:$C$10,"UNKNOWN_ITEM") -> 5200 | L72: 1 | M72: =K72*L72 -> 5200 | N72: 5200 | O72: pending
A73: 1076 | B73: 2026-11 | C73: Gaurav | D73: Yadav | E73: =PROPER(TRIM(C73)) -> Gaurav | F73: =PROPER(TRIM(D73)) -> Yadav | G73: East | H73: Sanjay Roy | I73: Cotton Kurta | J73: =VLOOKUP(I73,products!$A$2:$C$10,2,FALSE) -> Apparel | K73: =_xlfn.XLOOKUP(I73,products!$A$2:$A$10,products!$C$2:$C$10,"UNKNOWN_ITEM") -> 1400 | L73: 2 | M73: =K73*L73 -> 2800 | N73: 2800 | O73: completed
A74: 1080 | B74: 2026-11 | C74: Harsh | D74: Chopra | E74: =PROPER(TRIM(C74)) -> Harsh | F74: =PROPER(TRIM(D74)) -> Chopra | G74: East | H74: Sanjay Roy | I74: Bluetooth Speaker | J74: =VLOOKUP(I74,products!$A$2:$C$10,2,FALSE) -> Electronics | K74: =_xlfn.XLOOKUP(I74,products!$A$2:$A$10,products!$C$2:$C$10,"UNKNOWN_ITEM") -> 2800 | L74: 1 | M74: =K74*L74 -> 2800 | N74: 2800 | O74: completed
A75: 1032 | B75: 2026-10 | C75: karthik | D75: nair | E75: =PROPER(TRIM(C75)) -> Karthik | F75: =PROPER(TRIM(D75)) -> Nair | G75: East | H75: Sanjay Roy | I75: Table Lamp | J75: =VLOOKUP(I75,products!$A$2:$C$10,2,FALSE) -> Home | K75: =_xlfn.XLOOKUP(I75,products!$A$2:$A$10,products!$C$2:$C$10,"UNKNOWN_ITEM") -> 1100 | L75: 2 | M75: =K75*L75 -> 2200 | N75: 2200 | O75: completed
A76: 1075 | B76: 2026-11 | C76: Sneha | D76: Das | E76: =PROPER(TRIM(C76)) -> Sneha | F76: =PROPER(TRIM(D76)) -> Das | G76: West | H76: Neha Kulkarni | I76: Running Shoes | J76: =VLOOKUP(I76,products!$A$2:$C$10,2,FALSE) -> Apparel | K76: =_xlfn.XLOOKUP(I76,products!$A$2:$A$10,products!$C$2:$C$10,"UNKNOWN_ITEM") -> 3600 | L76: 1 | M76: =K76*L76 -> 3600 | N76: 3600 | O76: pending
A77: 1039 | B77: 2026-10 | C77: RAHUL | D77: VERMA | E77: =PROPER(TRIM(C77)) -> Rahul | F77: =PROPER(TRIM(D77)) -> Verma | G77: East | H77: Sanjay Roy | I77: Table Lamp | J77: =VLOOKUP(I77,products!$A$2:$C$10,2,FALSE) -> Home | K77: =_xlfn.XLOOKUP(I77,products!$A$2:$A$10,products!$C$2:$C$10,"UNKNOWN_ITEM") -> 1100 | L77: 2 | M77: =K77*L77 -> 2200 | N77: 2200 | O77: completed
... A91: 1089 | B91: 2026-11 | C91: MEERA | D91: Patil | E91: =PROPER(TRIM(C91)) -> Meera | F91: =PROPER(TRIM(D91)) -> Patil | G91: South | H91: Kavya Nair | I91: Table Lamp | J91: =VLOOKUP(I91,products!$A$2:$C$10,2,FALSE) -> Home | K91: =_xlfn.XLOOKUP(I91,products!$A$2:$A$10,products!$C$2:$C$10,"UNKNOWN_ITEM") -> 1100 | L91: 1 | M91: =K91*L91 -> 1100 | N91: 1100 | O91: completed
D93: Task-3 | E93: =_xlfn.XLOOKUP("Mystery Item",products!$A$2:$A$10,products!$C$2:$C$10,"UNKNOWN_ITEM") -> UNKNOWN_ITEM
E94: =_xlfn.XLOOKUP("Mystery Item",products!$A$2:$A$10,products!$C$2:$C$10,"UNKNOWN_ITEM") -> UNKNOWN_ITEM
...

Sheet products
A1: item | B1: category | C1: unit_price
A2: Air Fryer | B2: Home | C2: 5200
A3: Bedsheet Set | B3: Home | C3: 1900
A4: Bluetooth Speaker | B4: Electronics | C4: 2800
A5: Cotton Kurta | B5: Apparel | C5: 1400
A6: Denim Jacket | B6: Apparel | C6: 2500
A7: Running Shoes | B7: Apparel | C7: 3600
A8: Smart Watch | B8: Electronics | C8: 4500
A9: Table Lamp | B9: Home | C9: 1100
A10: Wireless Earbuds | B10: Electronics | C10: 3200
A12: Above one is imported csv file from Part-A

Sheet completed_orders
A1: order_id | B1: order_month | C1: clean_first_name | D1: clean_last_name | E1: region | F1: rep_name | G1: item | H1: category | I1: unit price | J1: quantity | K1: amount | L1: revenue_calc | M1: status | N1: Task-5 | O1: Calculation | P1: Values
A2: 1061 | B2: 2026-11 | C2: Nisha | D2: Mishra | E2: West | F2: Neha Kulkarni | G2: Air Fryer | H2: =VLOOKUP(G2,products!$A$2:$C$10,2,FALSE) -> Home | I2: =_xlfn.XLOOKUP(G2,products!$A$2:$A$10,products!$C$2:$C$10,"UNKNOWN_ITEM") -> 5200 | J2: 3 | K2: 15600 | L2: =I2*J2 -> 15600 | M2: completed | O2: Count | P2: =COUNT(K2:K64) -> 63
A3: 1065 | B3: 2026-11 | C3: Tanvi | D3: Thakur | E3: South | F3: Kavya Nair | G3: Air Fryer | H3: =VLOOKUP(G3,products!$A$2:$C$10,2,FALSE) -> Home | I3: =_xlfn.XLOOKUP(G3,products!$A$2:$A$10,products!$C$2:$C$10,"UNKNOWN_ITEM") -> 5200 | J3: 3 | K3: 15600 | L3: =I3*J3 -> 15600 | M3: completed | O3: Sum | P3: =SUM(K2:K64) -> 346200
A4: 1069 | B4: 2026-11 | C4: Aditya | D4: Rao | E4: East | F4: Sanjay Roy | G4: Air Fryer | H4: =VLOOKUP(G4,products!$A$2:$C$10,2,FALSE) -> Home | I4: =_xlfn.XLOOKUP(G4,products!$A$2:$A$10,products!$C$2:$C$10,"UNKNOWN_ITEM") -> 5200 | J4: 3 | K4: 15600 | L4: =I4*J4 -> 15600 | M4: completed | O4: Average | P4: =AVERAGE(K2:K64) -> 5495.2381
A5: 1077 | B5: 2026-11 | C5: Rahul | D5: Verma | E5: East | F5: Sanjay Roy | G5: Air Fryer | H5: =VLOOKUP(G5,products!$A$2:$C$10,2,FALSE) -> Home | I5: =_xlfn.XLOOKUP(G5,products!$A$2:$A$10,products!$C$2:$C$10,"UNKNOWN_ITEM") -> 5200 | J5: 3 | K5: 15600 | L5: =I5*J5 -> 15600 | M5: completed | O5: Minimum | P5: =MIN(K2:K64) -> 1100
A6: 1006 | B6: 2026-09 | C6: Vikram | D6: Singh | E6: North | F6: Arjun Mehta | G6: Smart Watch | H6: =VLOOKUP(G6,products!$A$2:$C$10,2,FALSE) -> Electronics | I6: =_xlfn.XLOOKUP(G6,products!$A$2:$A$10,products!$C$2:$C$10,"UNKNOWN_ITEM") -> 4500 | J6: 3 | K6: 13500 | L6: =I6*J6 -> 13500 | M6: completed | O6: Maxmimum | P6: =MAX(K2:K64) -> 15600
A7: 1040 | B7: 2026-10 | C7: Aarav | D7: Sharma | E7: North | F7: Arjun Mehta | G7: Smart Watch | H7: =VLOOKUP(G7,products!$A$2:$C$10,2,FALSE) -> Electronics | I7: =_xlfn.XLOOKUP(G7,products!$A$2:$A$10,products!$C$2:$C$10,"UNKNOWN_ITEM") -> 4500 | J7: 3 | K7: 13500 | L7: =I7*J7 -> 13500 | M7: completed
A8: 1021 | B8: 2026-09 | C8: Manoj | D8: Desai | E8: North | F8: Arjun Mehta | G8: Air Fryer | H8: =VLOOKUP(G8,products!$A$2:$C$10,2,FALSE) -> Home | I8: =_xlfn.XLOOKUP(G8,products!$A$2:$A$10,products!$C$2:$C$10,"UNKNOWN_ITEM") -> 5200 | J8: 2 | K8: 10400 | L8: =I8*J8 -> 10400 | M8: completed
A9: 1022 | B9: 2026-09 | C9: Vikram | D9: Singh | E9: North | F9: Arjun Mehta | G9: Air Fryer | H9: =VLOOKUP(G9,products!$A$2:$C$10,2,FALSE) -> Home | I9: =_xlfn.XLOOKUP(G9,products!$A$2:$A$10,products!$C$2:$C$10,"UNKNOWN_ITEM") -> 5200 | J9: 2 | K9: 10400 | L9: =I9*J9 -> 10400 | M9: completed
A10: 1083 | B10: 2026-11 | C10: Lakshmi | D10: Kapoor | E10: South | F10: Kavya Nair | G10: Air Fryer | H10: =VLOOKUP(G10,products!$A$2:$C$10,2,FALSE) -> Home | I10: =_xlfn.XLOOKUP(G10,products!$A$2:$A$10,products!$C$2:$C$10,"UNKNOWN_ITEM") -> 5200 | J10: 2 | K10: 10400 | L10: =I10*J10 -> 10400 | M10: completed
A11: 1054 | B11: 2026-10 | C11: Manoj | D11: Desai | E11: North | F11: Arjun Mehta | G11: Wireless Earbuds | H11: =VLOOKUP(G11,products!$A$2:$C$10,2,FALSE) -> Electronics | I11: =_xlfn.XLOOKUP(G11,products!$A$2:$A$10,products!$C$2:$C$10,"UNKNOWN_ITEM") -> 3200 | J11: 3 | K11: 9600 | L11: =I11*J11 -> 9600 | M11: completed
A12: 1090 | B12: 2026-11 | C12: Karthik | D12: Nair | E12: East | F12: Sanjay Roy | G12: Wireless Earbuds | H12: =VLOOKUP(G12,products!$A$2:$C$10,2,FALSE) -> Electronics | I12: =_xlfn.XLOOKUP(G12,products!$A$2:$A$10,products!$C$2:$C$10,"UNKNOWN_ITEM") -> 3200 | J12: 3 | K12: 9600 | L12: =I12*J12 -> 9600 | M12: completed
A13: 1015 | B13: 2026-09 | C13: Lakshmi | D13: Kapoor | E13: South | F13: Kavya Nair | G13: Smart Watch | H13: =VLOOKUP(G13,products!$A$2:$C$10,2,FALSE) -> Electronics | I13: =_xlfn.XLOOKUP(G13,products!$A$2:$A$10,products!$C$2:$C$10,"UNKNOWN_ITEM") -> 4500 | J13: 2 | K13: 9000 | L13: =I13*J13 -> 9000 | M13: completed
A14: 1049 | B14: 2026-10 | C14: Aarav | D14: Sharma | E14: North | F14: Arjun Mehta | G14: Smart Watch | H14: =VLOOKUP(G14,products!$A$2:$C$10,2,FALSE) -> Electronics | I14: =_xlfn.XLOOKUP(G14,products!$A$2:$A$10,products!$C$2:$C$10,"UNKNOWN_ITEM") -> 4500 | J14: 2 | K14: 9000 | L14: =I14*J14 -> 9000 | M14: completed
A15: 1016 | B15: 2026-09 | C15: Pooja | D15: Menon | E15: West | F15: Neha Kulkarni | G15: Denim Jacket | H15: =VLOOKUP(G15,products!$A$2:$C$10,2,FALSE) -> Apparel | I15: =_xlfn.XLOOKUP(G15,products!$A$2:$A$10,products!$C$2:$C$10,"UNKNOWN_ITEM") -> 2500 | J15: 3 | K15: 7500 | L15: =I15*J15 -> 7500 | M15: completed
A16: 1019 | B16: 2026-09 | C16: Vikram | D16: Singh | E16: North | F16: Arjun Mehta | G16: Running Shoes | H16: =VLOOKUP(G16,products!$A$2:$C$10,2,FALSE) -> Apparel | I16: =_xlfn.XLOOKUP(G16,products!$A$2:$A$10,products!$C$2:$C$10,"UNKNOWN_ITEM") -> 3600 | J16: 2 | K16: 7200 | L16: =I16*J16 -> 7200 | M16: completed
A17: 1034 | B17: 2026-10 | C17: Divya | D17: Gupta | E17: West | F17: Neha Kulkarni | G17: Running Shoes | H17: =VLOOKUP(G17,products!$A$2:$C$10,2,FALSE) -> Apparel | I17: =_xlfn.XLOOKUP(G17,products!$A$2:$A$10,products!$C$2:$C$10,"UNKNOWN_ITEM") -> 3600 | J17: 2 | K17: 7200 | L17: =I17*J17 -> 7200 | M17: completed
A18: 1074 | B18: 2026-11 | C18: Nisha | D18: Mishra | E18: West | F18: Neha Kulkarni | G18: Running Shoes | H18: =VLOOKUP(G18,products!$A$2:$C$10,2,FALSE) -> Apparel | I18: =_xlfn.XLOOKUP(G18,products!$A$2:$A$10,products!$C$2:$C$10,"UNKNOWN_ITEM") -> 3600 | J18: 2 | K18: 7200 | L18: =I18*J18 -> 7200 | M18: completed
... A64: 1089 | B64: 2026-11 | C64: Meera | D64: Patil | E64: South | F64: Kavya Nair | G64: Table Lamp | H64: =VLOOKUP(G64,products!$A$2:$C$10,2,FALSE) -> Home | I64: =_xlfn.XLOOKUP(G64,products!$A$2:$A$10,products!$C$2:$C$10,"UNKNOWN_ITEM") -> 1100 | J64: 1 | K64: 1100 | L64: =I64*J64 -> 1100 | M64: completed
J65: =SUM(J2:J64) -> 106

Sheet Pivot table-1
A2: Task-7
A3: Sum of amount | B3: region
A4: category | B4: East | C4: North | D4: South | E4: West | F4: Grand Total
A5: Apparel | B5: 10600 | C5: 19400 | D5: 10000 | E5: 37500 | F5: 77500
A6: Electronics | B6: 21400 | C6: 73400 | D6: 28700 | E6: 18800 | F6: 142300
A7: Home | B7: 37500 | C7: 26500 | D7: 43800 | E7: 18600 | F7: 126400
A8: Grand Total | B8: 69500 | C8: 119300 | D8: 82500 | E8: 74900 | F8: 346200

Sheet Pivot table-2
A2: Task-7
A3: order_month | B3: Sum of order_id | C3: Sum of amount
A4: 2026-09 | B4: 19307 | C4: 98300
A5: 2026-10 | B5: 20832 | C5: 93100
A6: 2026-11 | B6: 25823 | C6: 154800
A7: Grand Total | B7: 65962 | C7: 346200
